Traceback (most recent call last):
  File "/home/tiagoburiol/.local/lib/python3.12/site-packages/jupyter_cache/executors/utils.py", line 58, in single_nb_execution
    executenb(
  File "/home/tiagoburiol/anaconda3/lib/python3.12/site-packages/nbclient/client.py", line 1305, in execute
    return NotebookClient(nb=nb, resources=resources, km=km, **kwargs).execute()
           ^^^^^^^^^^^^^^^^^^^^^^^^^^^^^^^^^^^^^^^^^^^^^^^^^^^^^^^^^^^^^^^^^^^^^
  File "/home/tiagoburiol/anaconda3/lib/python3.12/site-packages/jupyter_core/utils/__init__.py", line 165, in wrapped
    return loop.run_until_complete(inner)
           ^^^^^^^^^^^^^^^^^^^^^^^^^^^^^^
  File "/home/tiagoburiol/anaconda3/lib/python3.12/asyncio/base_events.py", line 687, in run_until_complete
    return future.result()
           ^^^^^^^^^^^^^^^
  File "/home/tiagoburiol/anaconda3/lib/python3.12/site-packages/nbclient/client.py", line 705, in async_execute
    await self.async_execute_cell(
  File "/home/tiagoburiol/anaconda3/lib/python3.12/site-packages/nbclient/client.py", line 1058, in async_execute_cell
    await self._check_raise_for_error(cell, cell_index, exec_reply)
  File "/home/tiagoburiol/anaconda3/lib/python3.12/site-packages/nbclient/client.py", line 914, in _check_raise_for_error
    raise CellExecutionError.from_cell_and_msg(cell, exec_reply_content)
nbclient.exceptions.CellExecutionError: An error occurred while executing the following cell:
------------------
# indentation 
if 1 < 0:
    print("x  maior que y")
        print("x segue sendo maior que y")  #NÃ£o estÃ£o ao mesmo nÃ­vel de espaÃ§amento
------------------


[0;36m  Cell [0;32mIn[5], line 4[0;36m[0m
[0;31m    print("x segue sendo maior que y")  #NÃ£o estÃ£o ao mesmo nÃ­vel de espaÃ§amento[0m
[0m    ^[0m
[0;31mIndentationError[0m[0;31m:[0m unexpected indent


