Traceback (most recent call last):
  File "/home/tiagoburiol/.local/lib/python3.12/site-packages/jupyter_cache/executors/utils.py", line 58, in single_nb_execution
    executenb(
  File "/home/tiagoburiol/anaconda3/lib/python3.12/site-packages/nbclient/client.py", line 1305, in execute
    return NotebookClient(nb=nb, resources=resources, km=km, **kwargs).execute()
           ^^^^^^^^^^^^^^^^^^^^^^^^^^^^^^^^^^^^^^^^^^^^^^^^^^^^^^^^^^^^^^^^^^^^^
  File "/home/tiagoburiol/anaconda3/lib/python3.12/site-packages/jupyter_core/utils/__init__.py", line 165, in wrapped
    return loop.run_until_complete(inner)
           ^^^^^^^^^^^^^^^^^^^^^^^^^^^^^^
  File "/home/tiagoburiol/anaconda3/lib/python3.12/asyncio/base_events.py", line 687, in run_until_complete
    return future.result()
           ^^^^^^^^^^^^^^^
  File "/home/tiagoburiol/anaconda3/lib/python3.12/site-packages/nbclient/client.py", line 705, in async_execute
    await self.async_execute_cell(
  File "/home/tiagoburiol/anaconda3/lib/python3.12/site-packages/nbclient/client.py", line 1058, in async_execute_cell
    await self._check_raise_for_error(cell, cell_index, exec_reply)
  File "/home/tiagoburiol/anaconda3/lib/python3.12/site-packages/nbclient/client.py", line 914, in _check_raise_for_error
    raise CellExecutionError.from_cell_and_msg(cell, exec_reply_content)
nbclient.exceptions.CellExecutionError: An error occurred while executing the following cell:
------------------
% matplotlib inline
import numpy as np
import matplotlib.pyplot as plt

h = 0.5 #passo
x0 = 0.0
xn = 4.0

# criamos a lista com os pontos xi
X = np.arange(x0, xn+h, h) 
print ("pontos xi:", X)

# lista com y0, a ser preenchida pelos yi
Y = [1.0]                  

# entramos com f(x,y)
f = lambda x: -2*x**3 + 12*x**2 - 20*x + 8.5

# laço para ir calculando os yi e preenchendo a lista
for x in X[0:-1]:
    Y.append(Y[-1] + f(x)*h ) #Y[-1] é o último yi calculado
    
# imprime
print ("pontos yi:", Y)

# plota
plt.plot(X, Y, "r-")
plt.grid()
plt.show()
------------------

----- stderr -----
UsageError: Line magic function `%` not found.
------------------



